reported_result/report-7/RT/output/output3.txt

Limit	1	1	6	4	8	SELL	0	---	0
NewOrderRs	Accepted
	Trades	0
	Orders	1
	Order	Limit	1	1	6	4	8	SELL	0	---	0
	Credits	7
	Credit	1	18
	Credit	2	5
	Credit	3	11
	Credit	4	9
	Credit	5	12
	Credit	6	15
	Credit	7	9
	Ownerships	7
	Ownership	1	47
	Ownership	2	54
	Ownership	3	55
	Ownership	4	17
	Ownership	5	17
	Ownership	6	14
	Ownership	7	21
	ReferencePrice	5
	StaticPriceBandLowerLimit	0.6
	StaticPriceBandUpperLimit	0.8
	TotalShares	100
	OwnershipUpperLimit	0.2
	TickSize	1
	LotSize	1
Limit	2	3	4	3	3	SELL	0	FAK	0
NewOrderRs	Eliminated
	Trades	0
	Orders	1
	Order	Limit	1	1	6	4	8	SELL	0	---	0
	Credits	7
	Credit	1	18
	Credit	2	5
	Credit	3	11
	Credit	4	9
	Credit	5	12
	Credit	6	15
	Credit	7	9
	Ownerships	7
	Ownership	1	47
	Ownership	2	54
	Ownership	3	55
	Ownership	4	17
	Ownership	5	17
	Ownership	6	14
	Ownership	7	21
	ReferencePrice	5
	StaticPriceBandLowerLimit	0.6
	StaticPriceBandUpperLimit	0.8
	TotalShares	100
	OwnershipUpperLimit	0.2
	TickSize	1
	LotSize	1
Iceberg	3	5	4	7	8	SELL	0	---	0
NewOrderRs	Accepted
	Trades	0
	Orders	2
	Order	Limit	1	1	6	4	8	SELL	0	---	0
	Order	Iceberg	3	5	4	7	8	SELL	0	---	8
	Credits	7
	Credit	1	18
	Credit	2	5
	Credit	3	11
	Credit	4	9
	Credit	5	12
	Credit	6	15
	Credit	7	9
	Ownerships	7
	Ownership	1	47
	Ownership	2	54
	Ownership	3	55
	Ownership	4	17
	Ownership	5	17
	Ownership	6	14
	Ownership	7	21
	ReferencePrice	5
	StaticPriceBandLowerLimit	0.6
	StaticPriceBandUpperLimit	0.8
	TotalShares	100
	OwnershipUpperLimit	0.2
	TickSize	1
	LotSize	1
Iceberg	4	1	4	3	3	BUY 	0	---	0
NewOrderRs	Rejected
	Trades	0
	Orders	2
	Order	Limit	1	1	6	4	8	SELL	0	---	0
	Order	Iceberg	3	5	4	7	8	SELL	0	---	8
	Credits	7
	Credit	1	18
	Credit	2	5
	Credit	3	11
	Credit	4	9
	Credit	5	12
	Credit	6	15
	Credit	7	9
	Ownerships	7
	Ownership	1	47
	Ownership	2	54
	Ownership	3	55
	Ownership	4	17
	Ownership	5	17
	Ownership	6	14
	Ownership	7	21
	ReferencePrice	5
	StaticPriceBandLowerLimit	0.6
	StaticPriceBandUpperLimit	0.8
	TotalShares	100
	OwnershipUpperLimit	0.2
	TickSize	1
	LotSize	1
CancelOrderRs	Rejected
	Orders	2
	Order	Limit	1	1	6	4	8	SELL	0	---	0
	Order	Iceberg	3	5	4	7	8	SELL	0	---	8
	Credits	7
	Credit	1	18
	Credit	2	5
	Credit	3	11
	Credit	4	9
	Credit	5	12
	Credit	6	15
	Credit	7	9
	Ownerships	7
	Ownership	1	47
	Ownership	2	54
	Ownership	3	55
	Ownership	4	17
	Ownership	5	17
	Ownership	6	14
	Ownership	7	21
	ReferencePrice	5
	StaticPriceBandLowerLimit	0.6
	StaticPriceBandUpperLimit	0.8
	TotalShares	100
	OwnershipUpperLimit	0.2
	TickSize	1
	LotSize	1
Iceberg	6	1	5	4	8	SELL	0	---	0
NewOrderRs	Accepted
	Trades	0
	Orders	3
	Order	Limit	1	1	6	4	8	SELL	0	---	0
	Order	Iceberg	6	1	5	4	8	SELL	0	---	4
	Order	Iceberg	3	5	4	7	8	SELL	0	---	8
	Credits	7
	Credit	1	18
	Credit	2	5
	Credit	3	11
	Credit	4	9
	Credit	5	12
	Credit	6	15
	Credit	7	9
	Ownerships	7
	Ownership	1	47
	Ownership	2	54
	Ownership	3	55
	Ownership	4	17
	Ownership	5	17
	Ownership	6	14
	Ownership	7	21
	ReferencePrice	5
	StaticPriceBandLowerLimit	0.6
	StaticPriceBandUpperLimit	0.8
	TotalShares	100
	OwnershipUpperLimit	0.2
	TickSize	1
	LotSize	1
Limit	7	4	1	6	5	SELL	2	---	0
NewOrderRs	Eliminated
	Trades	0
	Orders	3
	Order	Limit	1	1	6	4	8	SELL	0	---	0
	Order	Iceberg	6	1	5	4	8	SELL	0	---	4
	Order	Iceberg	3	5	4	7	8	SELL	0	---	8
	Credits	7
	Credit	1	18
	Credit	2	5
	Credit	3	11
	Credit	4	9
	Credit	5	12
	Credit	6	15
	Credit	7	9
	Ownerships	7
	Ownership	1	47
	Ownership	2	54
	Ownership	3	55
	Ownership	4	17
	Ownership	5	17
	Ownership	6	14
	Ownership	7	21
	ReferencePrice	5
	StaticPriceBandLowerLimit	0.6
	StaticPriceBandUpperLimit	0.8
	TotalShares	100
	OwnershipUpperLimit	0.2
	TickSize	1
	LotSize	1
Iceberg	8	5	4	3	4	SELL	0	---	0
NewOrderRs	Accepted
	Trades	0
	Orders	4
	Order	Iceberg	8	5	4	3	4	SELL	0	---	4
	Order	Limit	1	1	6	4	8	SELL	0	---	0
	Order	Iceberg	6	1	5	4	8	SELL	0	---	4
	Order	Iceberg	3	5	4	7	8	SELL	0	---	8
	Credits	7
	Credit	1	18
	Credit	2	5
	Credit	3	11
	Credit	4	9
	Credit	5	12
	Credit	6	15
	Credit	7	9
	Ownerships	7
	Ownership	1	47
	Ownership	2	54
	Ownership	3	55
	Ownership	4	17
	Ownership	5	17
	Ownership	6	14
	Ownership	7	21
	ReferencePrice	5
	StaticPriceBandLowerLimit	0.6
	StaticPriceBandUpperLimit	0.8
	TotalShares	100
	OwnershipUpperLimit	0.2
	TickSize	1
	LotSize	1
Limit	9	3	4	9	3	BUY 	1	---	0
NewOrderRs	Rejected
	Trades	0
	Orders	4
	Order	Iceberg	8	5	4	3	4	SELL	0	---	4
	Order	Limit	1	1	6	4	8	SELL	0	---	0
	Order	Iceberg	6	1	5	4	8	SELL	0	---	4
	Order	Iceberg	3	5	4	7	8	SELL	0	---	8
	Credits	7
	Credit	1	18
	Credit	2	5
	Credit	3	11
	Credit	4	9
	Credit	5	12
	Credit	6	15
	Credit	7	9
	Ownerships	7
	Ownership	1	47
	Ownership	2	54
	Ownership	3	55
	Ownership	4	17
	Ownership	5	17
	Ownership	6	14
	Ownership	7	21
	ReferencePrice	5
	StaticPriceBandLowerLimit	0.6
	StaticPriceBandUpperLimit	0.8
	TotalShares	100
	OwnershipUpperLimit	0.2
	TickSize	1
	LotSize	1
Iceberg	10	3	4	9	7	BUY 	4	---	0
ReplaceOrderRs	Rejected
	Trades	0
	Orders	4
	Order	Iceberg	8	5	4	3	4	SELL	0	---	4
	Order	Limit	1	1	6	4	8	SELL	0	---	0
	Order	Iceberg	6	1	5	4	8	SELL	0	---	4
	Order	Iceberg	3	5	4	7	8	SELL	0	---	8
	Credits	7
	Credit	1	18
	Credit	2	5
	Credit	3	11
	Credit	4	9
	Credit	5	12
	Credit	6	15
	Credit	7	9
	Ownerships	7
	Ownership	1	47
	Ownership	2	54
	Ownership	3	55
	Ownership	4	17
	Ownership	5	17
	Ownership	6	14
	Ownership	7	21
	ReferencePrice	5
	StaticPriceBandLowerLimit	0.6
	StaticPriceBandUpperLimit	0.8
	TotalShares	100
	OwnershipUpperLimit	0.2
	TickSize	1
	LotSize	1
Limit	11	5	7	7	8	SELL	8	---	0
NewOrderRs	Eliminated
	Trades	0
	Orders	4
	Order	Iceberg	8	5	4	3	4	SELL	0	---	4
	Order	Limit	1	1	6	4	8	SELL	0	---	0
	Order	Iceberg	6	1	5	4	8	SELL	0	---	4
	Order	Iceberg	3	5	4	7	8	SELL	0	---	8
	Credits	7
	Credit	1	18
	Credit	2	5
	Credit	3	11
	Credit	4	9
	Credit	5	12
	Credit	6	15
	Credit	7	9
	Ownerships	7
	Ownership	1	47
	Ownership	2	54
	Ownership	3	55
	Ownership	4	17
	Ownership	5	17
	Ownership	6	14
	Ownership	7	21
	ReferencePrice	5
	StaticPriceBandLowerLimit	0.6
	StaticPriceBandUpperLimit	0.8
	TotalShares	100
	OwnershipUpperLimit	0.2
	TickSize	1
	LotSize	1
Iceberg	12	7	2	6	7	SELL	0	---	0
NewOrderRs	Accepted
	Trades	0
	Orders	5
	Order	Iceberg	8	5	4	3	4	SELL	0	---	4
	Order	Limit	1	1	6	4	8	SELL	0	---	0
	Order	Iceberg	6	1	5	4	8	SELL	0	---	4
	Order	Iceberg	12	7	2	6	7	SELL	0	---	2
	Order	Iceberg	3	5	4	7	8	SELL	0	---	8
	Credits	7
	Credit	1	18
	Credit	2	5
	Credit	3	11
	Credit	4	9
	Credit	5	12
	Credit	6	15
	Credit	7	9
	Ownerships	7
	Ownership	1	47
	Ownership	2	54
	Ownership	3	55
	Ownership	4	17
	Ownership	5	17
	Ownership	6	14
	Ownership	7	21
	ReferencePrice	5
	StaticPriceBandLowerLimit	0.6
	StaticPriceBandUpperLimit	0.8
	TotalShares	100
	OwnershipUpperLimit	0.2
	TickSize	1
	LotSize	1
Limit	13	4	2	10	3	BUY 	3	---	0
NewOrderRs	Rejected
	Trades	0
	Orders	5
	Order	Iceberg	8	5	4	3	4	SELL	0	---	4
	Order	Limit	1	1	6	4	8	SELL	0	---	0
	Order	Iceberg	6	1	5	4	8	SELL	0	---	4
	Order	Iceberg	12	7	2	6	7	SELL	0	---	2
	Order	Iceberg	3	5	4	7	8	SELL	0	---	8
	Credits	7
	Credit	1	18
	Credit	2	5
	Credit	3	11
	Credit	4	9
	Credit	5	12
	Credit	6	15
	Credit	7	9
	Ownerships	7
	Ownership	1	47
	Ownership	2	54
	Ownership	3	55
	Ownership	4	17
	Ownership	5	17
	Ownership	6	14
	Ownership	7	21
	ReferencePrice	5
	StaticPriceBandLowerLimit	0.6
	StaticPriceBandUpperLimit	0.8
	TotalShares	100
	OwnershipUpperLimit	0.2
	TickSize	1
	LotSize	1
Limit	14	5	2	9	3	BUY 	1	---	0
NewOrderRs	Rejected
	Trades	0
	Orders	5
	Order	Iceberg	8	5	4	3	4	SELL	0	---	4
	Order	Limit	1	1	6	4	8	SELL	0	---	0
	Order	Iceberg	6	1	5	4	8	SELL	0	---	4
	Order	Iceberg	12	7	2	6	7	SELL	0	---	2
	Order	Iceberg	3	5	4	7	8	SELL	0	---	8
	Credits	7
	Credit	1	18
	Credit	2	5
	Credit	3	11
	Credit	4	9
	Credit	5	12
	Credit	6	15
	Credit	7	9
	Ownerships	7
	Ownership	1	47
	Ownership	2	54
	Ownership	3	55
	Ownership	4	17
	Ownership	5	17
	Ownership	6	14
	Ownership	7	21
	ReferencePrice	5
	StaticPriceBandLowerLimit	0.6
	StaticPriceBandUpperLimit	0.8
	TotalShares	100
	OwnershipUpperLimit	0.2
	TickSize	1
	LotSize	1
CancelOrderRs	Rejected
	Orders	5
	Order	Iceberg	8	5	4	3	4	SELL	0	---	4
	Order	Limit	1	1	6	4	8	SELL	0	---	0
	Order	Iceberg	6	1	5	4	8	SELL	0	---	4
	Order	Iceberg	12	7	2	6	7	SELL	0	---	2
