reported_result/report-7/RT/output/output8.txt

Iceberg	1	6	1	2	1	SELL	1	---	0
NewOrderRs	Eliminated
	Trades	0
	Orders	0
	Credits	7
	Credit	1	18
	Credit	2	13
	Credit	3	4
	Credit	4	13
	Credit	5	10
	Credit	6	9
	Credit	7	4
	Ownerships	7
	Ownership	1	67
	Ownership	2	26
	Ownership	3	63
	Ownership	4	97
	Ownership	5	23
	Ownership	6	71
	Ownership	7	90
	ReferencePrice	5
	StaticPriceBandLowerLimit	0.6
	StaticPriceBandUpperLimit	0.8
	TotalShares	100
	OwnershipUpperLimit	0.2
	TickSize	1
	LotSize	1
Limit	2	1	3	8	5	BUY 	0	FAK	0
NewOrderRs	Rejected
	Trades	0
	Orders	0
	Credits	7
	Credit	1	18
	Credit	2	13
	Credit	3	4
	Credit	4	13
	Credit	5	10
	Credit	6	9
	Credit	7	4
	Ownerships	7
	Ownership	1	67
	Ownership	2	26
	Ownership	3	63
	Ownership	4	97
	Ownership	5	23
	Ownership	6	71
	Ownership	7	90
	ReferencePrice	5
	StaticPriceBandLowerLimit	0.6
	StaticPriceBandUpperLimit	0.8
	TotalShares	100
	OwnershipUpperLimit	0.2
	TickSize	1
	LotSize	1
Limit	3	5	4	3	5	SELL	0	---	0
NewOrderRs	Accepted
	Trades	0
	Orders	1
	Order	Limit	3	5	4	3	5	SELL	0	---	0
	Credits	7
	Credit	1	18
	Credit	2	13
	Credit	3	4
	Credit	4	13
	Credit	5	10
	Credit	6	9
	Credit	7	4
	Ownerships	7
	Ownership	1	67
	Ownership	2	26
	Ownership	3	63
	Ownership	4	97
	Ownership	5	23
	Ownership	6	71
	Ownership	7	90
	ReferencePrice	5
	StaticPriceBandLowerLimit	0.6
	StaticPriceBandUpperLimit	0.8
	TotalShares	100
	OwnershipUpperLimit	0.2
	TickSize	1
	LotSize	1
Limit	4	2	2	7	7	BUY 	2	---	0
NewOrderRs	Rejected
	Trades	0
	Orders	1
	Order	Limit	3	5	4	3	5	SELL	0	---	0
	Credits	7
	Credit	1	18
	Credit	2	13
	Credit	3	4
	Credit	4	13
	Credit	5	10
	Credit	6	9
	Credit	7	4
	Ownerships	7
	Ownership	1	67
	Ownership	2	26
	Ownership	3	63
	Ownership	4	97
	Ownership	5	23
	Ownership	6	71
	Ownership	7	90
	ReferencePrice	5
	StaticPriceBandLowerLimit	0.6
	StaticPriceBandUpperLimit	0.8
	TotalShares	100
	OwnershipUpperLimit	0.2
	TickSize	1
	LotSize	1
CancelOrderRs	Rejected
	Orders	1
	Order	Limit	3	5	4	3	5	SELL	0	---	0
	Credits	7
	Credit	1	18
	Credit	2	13
	Credit	3	4
	Credit	4	13
	Credit	5	10
	Credit	6	9
	Credit	7	4
	Ownerships	7
	Ownership	1	67
	Ownership	2	26
	Ownership	3	63
	Ownership	4	97
	Ownership	5	23
	Ownership	6	71
	Ownership	7	90
	ReferencePrice	5
	StaticPriceBandLowerLimit	0.6
	StaticPriceBandUpperLimit	0.8
	TotalShares	100
	OwnershipUpperLimit	0.2
	TickSize	1
	LotSize	1
Limit	6	2	4	10	8	SELL	5	---	0
NewOrderRs	Rejected
	Trades	0
	Orders	1
	Order	Limit	3	5	4	3	5	SELL	0	---	0
	Credits	7
	Credit	1	18
	Credit	2	13
	Credit	3	4
	Credit	4	13
	Credit	5	10
	Credit	6	9
	Credit	7	4
	Ownerships	7
	Ownership	1	67
	Ownership	2	26
	Ownership	3	63
	Ownership	4	97
	Ownership	5	23
	Ownership	6	71
	Ownership	7	90
	ReferencePrice	5
	StaticPriceBandLowerLimit	0.6
	StaticPriceBandUpperLimit	0.8
	TotalShares	100
	OwnershipUpperLimit	0.2
	TickSize	1
	LotSize	1
Iceberg	7	2	6	5	8	BUY 	5	---	0
NewOrderRs	Rejected
	Trades	0
	Orders	1
	Order	Limit	3	5	4	3	5	SELL	0	---	0
	Credits	7
	Credit	1	18
	Credit	2	13
	Credit	3	4
	Credit	4	13
	Credit	5	10
	Credit	6	9
	Credit	7	4
	Ownerships	7
	Ownership	1	67
	Ownership	2	26
	Ownership	3	63
	Ownership	4	97
	Ownership	5	23
	Ownership	6	71
	Ownership	7	90
	ReferencePrice	5
	StaticPriceBandLowerLimit	0.6
	StaticPriceBandUpperLimit	0.8
	TotalShares	100
	OwnershipUpperLimit	0.2
	TickSize	1
	LotSize	1
Limit	8	3	6	4	8	SELL	0	---	0
NewOrderRs	Accepted
	Trades	0
	Orders	2
	Order	Limit	3	5	4	3	5	SELL	0	---	0
	Order	Limit	8	3	6	4	8	SELL	0	---	0
	Credits	7
	Credit	1	18
	Credit	2	13
	Credit	3	4
	Credit	4	13
	Credit	5	10
	Credit	6	9
	Credit	7	4
	Ownerships	7
	Ownership	1	67
	Ownership	2	26
	Ownership	3	63
	Ownership	4	97
	Ownership	5	23
	Ownership	6	71
	Ownership	7	90
	ReferencePrice	5
	StaticPriceBandLowerLimit	0.6
	StaticPriceBandUpperLimit	0.8
	TotalShares	100
	OwnershipUpperLimit	0.2
	TickSize	1
	LotSize	1
Iceberg	9	6	6	6	8	SELL	4	---	0
NewOrderRs	Eliminated
	Trades	0
	Orders	2
	Order	Limit	3	5	4	3	5	SELL	0	---	0
	Order	Limit	8	3	6	4	8	SELL	0	---	0
	Credits	7
	Credit	1	18
	Credit	2	13
	Credit	3	4
	Credit	4	13
	Credit	5	10
	Credit	6	9
	Credit	7	4
	Ownerships	7
	Ownership	1	67
	Ownership	2	26
	Ownership	3	63
	Ownership	4	97
	Ownership	5	23
	Ownership	6	71
	Ownership	7	90
	ReferencePrice	5
	StaticPriceBandLowerLimit	0.6
	StaticPriceBandUpperLimit	0.8
	TotalShares	100
	OwnershipUpperLimit	0.2
	TickSize	1
	LotSize	1
Limit	10	6	6	9	6	SELL	1	---	0
ReplaceOrderRs	Rejected
	Trades	0
	Orders	2
	Order	Limit	3	5	4	3	5	SELL	0	---	0
	Order	Limit	8	3	6	4	8	SELL	0	---	0
	Credits	7
	Credit	1	18
	Credit	2	13
	Credit	3	4
	Credit	4	13
	Credit	5	10
	Credit	6	9
	Credit	7	4
	Ownerships	7
	Ownership	1	67
	Ownership	2	26
	Ownership	3	63
	Ownership	4	97
	Ownership	5	23
	Ownership	6	71
	Ownership	7	90
	ReferencePrice	5
	StaticPriceBandLowerLimit	0.6
	StaticPriceBandUpperLimit	0.8
	TotalShares	100
	OwnershipUpperLimit	0.2
	TickSize	1
	LotSize	1
Iceberg	11	1	2	6	3	SELL	0	---	0
NewOrderRs	Accepted
	Trades	0
	Orders	3
	Order	Limit	3	5	4	3	5	SELL	0	---	0
	Order	Limit	8	3	6	4	8	SELL	0	---	0
	Order	Iceberg	11	1	2	6	3	SELL	0	---	3
	Credits	7
	Credit	1	18
	Credit	2	13
	Credit	3	4
	Credit	4	13
	Credit	5	10
	Credit	6	9
	Credit	7	4
	Ownerships	7
	Ownership	1	67
	Ownership	2	26
	Ownership	3	63
	Ownership	4	97
	Ownership	5	23
	Ownership	6	71
	Ownership	7	90
	ReferencePrice	5
	StaticPriceBandLowerLimit	0.6
	StaticPriceBandUpperLimit	0.8
	TotalShares	100
	OwnershipUpperLimit	0.2
	TickSize	1
	LotSize	1
Limit	12	5	1	9	4	BUY 	0	---	0
NewOrderRs	Rejected
	Trades	0
	Orders	3
	Order	Limit	3	5	4	3	5	SELL	0	---	0
	Order	Limit	8	3	6	4	8	SELL	0	---	0
	Order	Iceberg	11	1	2	6	3	SELL	0	---	3
	Credits	7
	Credit	1	18
	Credit	2	13
	Credit	3	4
	Credit	4	13
	Credit	5	10
	Credit	6	9
	Credit	7	4
	Ownerships	7
	Ownership	1	67
	Ownership	2	26
	Ownership	3	63
	Ownership	4	97
	Ownership	5	23
	Ownership	6	71
	Ownership	7	90
	ReferencePrice	5
	StaticPriceBandLowerLimit	0.6
	StaticPriceBandUpperLimit	0.8
	TotalShares	100
	OwnershipUpperLimit	0.2
	TickSize	1
	LotSize	1
Iceberg	13	6	1	4	8	BUY 	1	---	0
NewOrderRs	Rejected
	Trades	0
	Orders	3
	Order	Limit	3	5	4	3	5	SELL	0	---	0
	Order	Limit	8	3	6	4	8	SELL	0	---	0
	Order	Iceberg	11	1	2	6	3	SELL	0	---	3
	Credits	7
	Credit	1	18
	Credit	2	13
	Credit	3	4
	Credit	4	13
	Credit	5	10
	Credit	6	9
	Credit	7	4
	Ownerships	7
	Ownership	1	67
	Ownership	2	26
	Ownership	3	63
	Ownership	4	97
	Ownership	5	23
	Ownership	6	71
	Ownership	7	90
	ReferencePrice	5
	StaticPriceBandLowerLimit	0.6
	StaticPriceBandUpperLimit	0.8
	TotalShares	100
	OwnershipUpperLimit	0.2
	TickSize	1
	LotSize	1
Limit	14	2	3	3	6	SELL	0	FAK	0
NewOrderRs	Eliminated
	Trades	0
	Orders	3
	Order	Limit	3	5	4	3	5	SELL	0	---	0
	Order	Limit	8	3	6	4	8	SELL	0	---	0
	Order	Iceberg	11	1	2	6	3	SELL	0	---	3
	Credits	7
	Credit	1	18
	Credit	2	13
	Credit	3	4
	Credit	4	13
	Credit	5	10
	Credit	6	9
	Credit	7	4
	Ownerships	7
	Ownership	1	67
	Ownership	2	26
	Ownership	3	63
	Ownership	4	97
	Ownership	5	23
	Ownership	6	71
	Ownership	7	90
	ReferencePrice	5
	StaticPriceBandLowerLimit	0.6
	StaticPriceBandUpperLimit	0.8
	TotalShares	100
	OwnershipUpperLimit	0.2
	TickSize	1
	LotSize	1
CancelOrderRs	Rejected
	Orders	3
	Order	Limit	3	5	4	3	5	SELL	0	---	0
	Order	Limit	8	3	6	4	8	SELL	0	---	0
	Order	Iceberg	11	1	2	6	3	SELL	0	---	3
	Credits	7
	Credit	1	18
	Credit	2	13
	Credit	3	4
	Credit	4	13
	Credit	5	10
	Credit	6	9
	Credit	7	4
	Ownerships	7
	Ownership	1	67
	Ownership	2	26
	Ownership	3	63
	Ownership	4	97
	Ownership	5	23
	Ownership	6	71
	Ownership	7	90
	ReferencePrice	5
	StaticPriceBandLowerLimit	0.6
	StaticPriceBandUpperLimit	0.8
	TotalShares	100
	OwnershipUpperLimit	0.2
	TickSize	1
	LotSize	1
Limit	16	2	6	1	5	SELL	0	---	0
NewOrderRs	Rejected
	Trades	0
	Orders	3
	Order	Limit	3	5	4	3	5	SELL	0	---	0
	Order	Limit	8	3	6	4	8	SELL	0	---	0
	Order	Iceberg	11	1	2	6	3	SELL	0	---	3
	Credits	7
	Credit	1	18
	Credit	2	13
	Credit	3	4
	Credit	4	13
	Credit	5	10
	Credit	6	9
	Credit	7	4
	Ownerships	7
	Ownership	1	67
	Ownership	2	26
	Ownership	3	63
	Ownership	4	97
	Ownership	5	23
	Ownership	6	71
	Ownership	7	90
	ReferencePrice	5
	StaticPriceBandLowerLimit	0.6
	StaticPriceBandUpperLimit	0.8
	TotalShares	100
	OwnershipUpperLimit	0.2
