reported_result/report-73/RT/output/output3.txt

Iceberg	1	3	1	7	6	BUY 	1	---	0
NewOrderRs	Rejected
	Trades	0
	Orders	0
	Credits	7
	Credit	1	16
	Credit	2	18
	Credit	3	11
	Credit	4	14
	Credit	5	14
	Credit	6	20
	Credit	7	14
	Ownerships	7
	Ownership	1	24
	Ownership	2	25
	Ownership	3	30
	Ownership	4	51
	Ownership	5	82
	Ownership	6	39
	Ownership	7	24
	ReferencePrice	5
	StaticPriceBandLowerLimit	0.6
	StaticPriceBandUpperLimit	0.8
	TotalShares	100
	OwnershipUpperLimit	0.2
	TickSize	1
	LotSize	1
Iceberg	2	7	2	6	5	BUY 	1	---	0
NewOrderRs	Rejected
	Trades	0
	Orders	0
	Credits	7
	Credit	1	16
	Credit	2	18
	Credit	3	11
	Credit	4	14
	Credit	5	14
	Credit	6	20
	Credit	7	14
	Ownerships	7
	Ownership	1	24
	Ownership	2	25
	Ownership	3	30
	Ownership	4	51
	Ownership	5	82
	Ownership	6	39
	Ownership	7	24
	ReferencePrice	5
	StaticPriceBandLowerLimit	0.6
	StaticPriceBandUpperLimit	0.8
	TotalShares	100
	OwnershipUpperLimit	0.2
	TickSize	1
	LotSize	1
Limit	3	2	2	7	1	SELL	0	---	0
NewOrderRs	Accepted
	Trades	0
	Orders	1
	Order	Limit	3	2	2	7	1	SELL	0	---	0
	Credits	7
	Credit	1	16
	Credit	2	18
	Credit	3	11
	Credit	4	14
	Credit	5	14
	Credit	6	20
	Credit	7	14
	Ownerships	7
	Ownership	1	24
	Ownership	2	25
	Ownership	3	30
	Ownership	4	51
	Ownership	5	82
	Ownership	6	39
	Ownership	7	24
	ReferencePrice	5
	StaticPriceBandLowerLimit	0.6
	StaticPriceBandUpperLimit	0.8
	TotalShares	100
	OwnershipUpperLimit	0.2
	TickSize	1
	LotSize	1
Limit	4	4	6	7	5	BUY 	0	FAK	0
NewOrderRs	Rejected
	Trades	0
	Orders	1
	Order	Limit	3	2	2	7	1	SELL	0	---	0
	Credits	7
	Credit	1	16
	Credit	2	18
	Credit	3	11
	Credit	4	14
	Credit	5	14
	Credit	6	20
	Credit	7	14
	Ownerships	7
	Ownership	1	24
	Ownership	2	25
	Ownership	3	30
	Ownership	4	51
	Ownership	5	82
	Ownership	6	39
	Ownership	7	24
	ReferencePrice	5
	StaticPriceBandLowerLimit	0.6
	StaticPriceBandUpperLimit	0.8
	TotalShares	100
	OwnershipUpperLimit	0.2
	TickSize	1
	LotSize	1
CancelOrderRs	Rejected
	Orders	1
	Order	Limit	3	2	2	7	1	SELL	0	---	0
	Credits	7
	Credit	1	16
	Credit	2	18
	Credit	3	11
	Credit	4	14
	Credit	5	14
	Credit	6	20
	Credit	7	14
	Ownerships	7
	Ownership	1	24
	Ownership	2	25
	Ownership	3	30
	Ownership	4	51
	Ownership	5	82
	Ownership	6	39
	Ownership	7	24
	ReferencePrice	5
	StaticPriceBandLowerLimit	0.6
	StaticPriceBandUpperLimit	0.8
	TotalShares	100
	OwnershipUpperLimit	0.2
	TickSize	1
	LotSize	1
Limit	6	2	1	9	7	BUY 	0	FAK	0
NewOrderRs	Rejected
	Trades	0
	Orders	1
	Order	Limit	3	2	2	7	1	SELL	0	---	0
	Credits	7
	Credit	1	16
	Credit	2	18
	Credit	3	11
	Credit	4	14
	Credit	5	14
	Credit	6	20
	Credit	7	14
	Ownerships	7
	Ownership	1	24
	Ownership	2	25
	Ownership	3	30
	Ownership	4	51
	Ownership	5	82
	Ownership	6	39
	Ownership	7	24
	ReferencePrice	5
	StaticPriceBandLowerLimit	0.6
	StaticPriceBandUpperLimit	0.8
	TotalShares	100
	OwnershipUpperLimit	0.2
	TickSize	1
	LotSize	1
Iceberg	7	3	6	8	6	BUY 	0	---	0
NewOrderRs	Rejected
	Trades	0
	Orders	1
	Order	Limit	3	2	2	7	1	SELL	0	---	0
	Credits	7
	Credit	1	16
	Credit	2	18
	Credit	3	11
	Credit	4	14
	Credit	5	14
	Credit	6	20
	Credit	7	14
	Ownerships	7
	Ownership	1	24
	Ownership	2	25
	Ownership	3	30
	Ownership	4	51
	Ownership	5	82
	Ownership	6	39
	Ownership	7	24
	ReferencePrice	5
	StaticPriceBandLowerLimit	0.6
	StaticPriceBandUpperLimit	0.8
	TotalShares	100
	OwnershipUpperLimit	0.2
	TickSize	1
	LotSize	1
Limit	8	5	4	2	1	SELL	0	---	0
NewOrderRs	Accepted
	Trades	0
	Orders	2
	Order	Limit	8	5	4	2	1	SELL	0	---	0
	Order	Limit	3	2	2	7	1	SELL	0	---	0
	Credits	7
	Credit	1	16
	Credit	2	18
	Credit	3	11
	Credit	4	14
	Credit	5	14
	Credit	6	20
	Credit	7	14
	Ownerships	7
	Ownership	1	24
	Ownership	2	25
	Ownership	3	30
	Ownership	4	51
	Ownership	5	82
	Ownership	6	39
	Ownership	7	24
	ReferencePrice	5
	StaticPriceBandLowerLimit	0.6
	StaticPriceBandUpperLimit	0.8
	TotalShares	100
	OwnershipUpperLimit	0.2
	TickSize	1
	LotSize	1
Limit	9	2	3	4	5	BUY 	0	FAK	0
NewOrderRs	Rejected
	Trades	0
	Orders	2
	Order	Limit	8	5	4	2	1	SELL	0	---	0
	Order	Limit	3	2	2	7	1	SELL	0	---	0
	Credits	7
	Credit	1	16
	Credit	2	18
	Credit	3	11
	Credit	4	14
	Credit	5	14
	Credit	6	20
	Credit	7	14
	Ownerships	7
	Ownership	1	24
	Ownership	2	25
	Ownership	3	30
	Ownership	4	51
	Ownership	5	82
	Ownership	6	39
	Ownership	7	24
	ReferencePrice	5
	StaticPriceBandLowerLimit	0.6
	StaticPriceBandUpperLimit	0.8
	TotalShares	100
	OwnershipUpperLimit	0.2
	TickSize	1
	LotSize	1
Iceberg	10	2	3	4	7	BUY 	0	---	0
ReplaceOrderRs	Rejected
	Trades	0
	Orders	2
	Order	Limit	8	5	4	2	1	SELL	0	---	0
	Order	Limit	3	2	2	7	1	SELL	0	---	0
	Credits	7
	Credit	1	16
	Credit	2	18
	Credit	3	11
	Credit	4	14
	Credit	5	14
	Credit	6	20
	Credit	7	14
	Ownerships	7
	Ownership	1	24
	Ownership	2	25
	Ownership	3	30
	Ownership	4	51
	Ownership	5	82
	Ownership	6	39
	Ownership	7	24
	ReferencePrice	5
	StaticPriceBandLowerLimit	0.6
	StaticPriceBandUpperLimit	0.8
	TotalShares	100
	OwnershipUpperLimit	0.2
	TickSize	1
	LotSize	1
